Workbook

Sheet CYLINDER COST
A1: ="BORE "&C17&" X STROKE "&C19&" X ROD "&C18&" ASSY" -> BORE 2.5" X STROKE 180MM X ROD 1.5" ASSY
A2: DRG NO : 7008707
A3: MANUFACTURING ITEMS
A4: Sl.No | B4: Description | C4: QTY | D4: Material | E4: ID / WIDTH | F4: OD /THICKNESS | G4: L | H4: STD PARTS | I4: RM Reference | J4: Weights | K4: RM Cost | L4: Machining Cost | M4: Total (USD)
A5: 1 | B5: TUBE | C5: 1 | D5: ST 52 | E5: 63.5 | F5: 73.025 | G5: 293 | I5: Circular Bar | J5: =IF(H5="",IF(I5="Circular bar",((PI()*POWER(F5/2000,2)-PI()*POWER(E5/2000,2))*G5/1000)*VLOOKUP(D5,$G$29:$I$56,3,false),IF(I5="Flat",(E5*F5*G5/(1000*1000*1000))*VLOOKUP(D5,$G$29:$I$56,3,false))),VLOOKUP(H5,$P$30:$R$577,2,false)) -> 2.3491153 | K5: =IF(B5="TUBE",IF(AND(E5>=20,E5<=32),H31,IF(AND(E5>=40,E5<=200),H32,"")),"") -> 1.45 | L5: ='Machining cost'!M3 -> 1.2422353 | M5: =(L5+K5*J5)*C5 -> 4.6484524
A6: =A5+1 -> 2 | B6: PISTON ROD | C6: 1 | D6: CK45-HARD CHROME | F6: 38.1 | G6: 386 | I6: Circular Bar | J6: =IF(H6="",IF(I6="Circular bar",((PI()*POWER(F6/2000,2)-PI()*POWER(E6/2000,2))*G6/1000)*VLOOKUP(D6,$G$29:$I$56,3,false),IF(I6="Flat",(E6*F6*G6/(1000*1000*1000))*VLOOKUP(D6,$G$29:$I$56,3,false))),VLOOKUP(H6,$P$30:$R$577,2,false)) -> 3.4545922 | K6: =IF(B6="PISTON ROD",IF(AND(F6>=12,F6<=26),H36,IF(F6>=26,H37,"")),"") -> 1.45 | L6: ='Machining cost'!M7 -> 1.1436471 | M6: =(L6+K6*J6)*C6 -> 6.1528058
A7: =A6+1 -> 3 | B7: PISTON | C7: 1 | D7: ASTM A36 | F7: 65 | G7: 45 | I7: Circular Bar | J7: =IF(H7="",IF(I7="Circular bar",((PI()*POWER(F7/2000,2)-PI()*POWER(E7/2000,2))*G7/1000)*VLOOKUP(D7,$G$29:$I$56,3,false),IF(I7="Flat",(E7*F7*G7/(1000*1000*1000))*VLOOKUP(D7,$G$29:$I$56,3,false))),VLOOKUP(H7,$P$30:$R$577,2,false)) -> 1.172192 | K7: =VLOOKUP(D7,$G$30:$I$57,2,false) -> 0.95 | L7: ='Machining cost'!M10 -> 0.70317647 | M7: =(L7+K7*J7)*C7 -> 1.8167589
A8: =A7+1 -> 4 | B8: GLAND | C8: 1 | D8: ASTM A536 65-45-12 | F8: 75 | G8: 65 | I8: Circular Bar | J8: =IF(H8="",IF(I8="Circular bar",((PI()*POWER(F8/2000,2)-PI()*POWER(E8/2000,2))*G8/1000)*VLOOKUP(D8,$G$29:$I$56,3,false),IF(I8="Flat",(E8*F8*G8/(1000*1000*1000))*VLOOKUP(D8,$G$29:$I$56,3,false))),VLOOKUP(H8,$P$30:$R$577,2,false)) -> 2.0962768 | K8: =VLOOKUP(D8,$G$30:$I$57,2,false) -> 1.1 | L8: ='Machining cost'!M13 -> 1.1436471 | M8: =(L8+K8*J8)*C8 -> 3.4495515
A9: 5 | B9: END CAP | C9: 1 | D9: ASTM A36 | F9: 75 | G9: 20 | I9: Circular Bar | J9: =IF(H9="",IF(I9="Circular bar",((PI()*POWER(F9/2000,2)-PI()*POWER(E9/2000,2))*G9/1000)*VLOOKUP(D9,$G$29:$I$56,3,false),IF(I9="Flat",(E9*F9*G9/(1000*1000*1000))*VLOOKUP(D9,$G$29:$I$56,3,false))),VLOOKUP(H9,$P$30:$R$577,2,false)) -> 0.69360475 | K9: =VLOOKUP(D9,$G$30:$I$57,2,false) -> 0.95 | L9: ='Machining cost'!M16 -> 0.60529412 | M9: =(L9+K9*J9)*C9 -> 1.2642186
A10: 6 | B10: ROD CLEVIS | C10: 1 | D10: ASTM A36 | F10: 60 | G10: 55 | I10: Circular Bar | J10: =IF(H10="",IF(I10="Circular bar",((PI()*POWER(F10/2000,2)-PI()*POWER(E10/2000,2))*G10/1000)*VLOOKUP(D10,$G$29:$I$56,3,false),IF(I10="Flat",(E10*F10*G10/(1000*1000*1000))*VLOOKUP(D10,$G$29:$I$56,3,false))),VLOOKUP(H10,$P$30:$R$577,2,false)) -> 1.2207444 | K10: =VLOOKUP(D10,$G$30:$I$57,2,false) -> 0.95 | L10: ='Machining cost'!M19 -> 0.65423529 | M10: =(L10+K10*J10)*C10 -> 1.8139424
A11: 7 | B11: BACK CLEVIS | C11: 1 | D11: ASTM A36 | F11: 60 | G11: 95 | I11: Circular Bar | J11: =IF(H11="",IF(I11="Circular bar",((PI()*POWER(F11/2000,2)-PI()*POWER(E11/2000,2))*G11/1000)*VLOOKUP(D11,$G$29:$I$56,3,false),IF(I11="Flat",(E11*F11*G11/(1000*1000*1000))*VLOOKUP(D11,$G$29:$I$56,3,false))),VLOOKUP(H11,$P$30:$R$577,2,false)) -> 2.1085584 | K11: =VLOOKUP(D11,$G$30:$I$57,2,false) -> 0.95 | L11: ='Machining cost'!M22 -> 0.75211765 | M11: =(L11+K11*J11)*C11 -> 2.7552482
A12: BOUGHT OUT ITEMS
A13: 1 | B13: SOCKET - 9/16"-18UNF | C13: 2 | I13: =RIGHT(B13,LEN(B13)-FIND("-",B13)) -> 9/16"-18UNF | J13: 0.02 | K13: =VLOOKUP(B13,$B$31:$E$1099,4,false) -> 0.41111111 | M13: =K13*C13 -> 0.82222222
A14: 2 | B14: Plug- 9/16"-18UNF | C14: 2 | I14: =RIGHT(B14,LEN(B14)-FIND("-",B14)) -> 9/16"-18UNF | J14: 0.02 | K14: =VLOOKUP(B14,$B$31:$E$1099,4,false) -> 0.08 | M14: =K14*C14 -> 0.16
A15: 3 | B15: SEAL KIT - 2.5” X 1.5” KGD | C15: 1 | I15: =RIGHT(B15,LEN(B15)-FIND("-",B15)) -> 2.5” X 1.5” KGD | J15: 0.02 | K15: =VLOOKUP(B15,$B$31:$E$1099,4,false) -> 2.1930233 | M15: =K15*C15 -> 2.1930233
I16: Total | J16: =SUM(J5:J15)+J10 -> 14.375828 | L16: =SUM(L5:L15) -> 6.2443529 | M16: =SUM(M5:M15) -> 25.076223
B17: BORE | C17: 2.5" | J17: WELDING COST | M17: =M16*4% -> 1.0030489
B18: ROD | C18: 1.5" | J18: ASSEMBLY | M18: =M16*1.5% -> 0.37614335
B19: STROKE | C19: 180MM | J19: TESTING | M19: =M16*1.75% -> 0.43883391
J20: PAINTING | M20: ='Paint cost'!B17 -> 1.0441287
J21: PACKING & FORWARDING | M21: =M16*2% -> 0.50152447
J22: 0 | M22: =M16*3% -> 0.7522867
J23: TOTAL | M23: =SUM(M16:M22) -> 29.192189
J24: 18 | M24: =M23*(J24+100)% -> 34.446784
J25: 30 | M25: =M24*(J25+100)% -> 44.780819 | O25: =M25/J16 -> 3.1150079
P28: Name | Q28: Weight | R28: Price
B29: SOCKET | G29: MATERIAL NAME | H29: COST | I29: Density | O29: NAME | P29: CUSTOM
B30: DESCRIPTION | C30: NAME | D30: WEIGHT | E30: PRICE | G30: ST 52 | H30: 1.45 | I30: 7850 | O30: TUBE | P30: 2" GLAND
B31: SOCKET - 1 1/16"-12 UNF | C31: 1 1/16"-12 UNF | D31: 0.02 | E31: 0.448 | G31: TUBE (ID 20-32) | H31: 2.1 | I31: 7850 | O31: PISTON ROD | P31: 2.25" GLAND
B32: SOCKET - 1-5/16"-12 UNF | C32: 1-5/16"-12 UNF | D32: 0.02 | E32: 0.76688889 | G32: TUBE (ID 33-200) | H32: 1.45 | I32: 7850 | O32: PISTON | P32: 2.5" GLAND
B33: SOCKET - 1/2"-20 UNF | C33: 1/2"-20 UNF | D33: 0.02 | E33: 0.15833333 | G33: CK45-HARD CHROME | H33: 1.45 | I33: 7850 | O33: GLAND | P33: 2.75" GLAND
B34: SOCKET - 3/4"-16UNF | C34: 3/4"-16UNF | D34: 0.02 | E34: 0.20555556 | G34: CK45-HOLLOW(HARD CH) | H34: 2.5 | I34: 7850 | O34: END CAP | P34: 3" GLAND
B35: SOCKET - 3/8" -24 UNF | C35: 3/8" -24 UNF | D35: 0.02 | E35: 0.12777778 | G35: CK45-INDUCTION HARD | H35: 2.8 | I35: 7850 | O35: CLEVIS | P35: 3.25" GLAND
B36: SOCKET - 5/8" -18 UNF | C36: 5/8" -18 UNF | D36: 0.02 | E36: 0.20688889 | G36: PISTON ROD (DIA 12-26) | H36: 2.3 | I36: 7850 | O36: MANIFOLD | P36: 3.5" GLAND
B37: SOCKET - 7/16"-20UNF | C37: 7/16"-20UNF | D37: 0.02 | E37: 0.12777778 | G37: PISTON ROD (DIA >26) | H37: 1.45 | I37: 7850 | O37: FEEDER TUBE | P37: 3.75" GLAND
B38: SOCKET - 7/8"-14UNF | C38: 7/8"-14UNF | D38: 0.02 | E38: 0.32644444 | G38: ASTM A536 65-45-12 | H38: 1.1 | I38: 7300 | O38: NUT | P38: 4" GLAND
B39: SOCKET - 9/16"-18UNF | C39: 9/16"-18UNF | D39: 0.02 | E39: 0.41111111 | G39: ASTM A536 80-55-06 | H39: 1.5 | I39: 7300 | O39: SOCKET | P39: 4.25" GLAND
B40: SOCKET - 5/8"-18UNF SOCKET-SPL | C40: 5/8"-18UNF SOCKET-SPL | D40: 0.02 | E40: 0.18933333 | G40: ASTM A36 | H40: 0.95 | I40: 7850 | O40: PIN VALVE | P40: 4.5" GLAND
B41: SOCKET - 9/16"-18 UNF SAE#6 SOCKET-SPL [DD SK 27 A416] | C41: 9/16"-18 UNF SAE#6 SOCKET-SPL | D41: 0.02 | E41: 0.26333333 | G41: EN8 | H41: 1 | I41: 7850 | O41: ADAPTER | P41: 4.75" GLAND
B42: SOCKET - 9/16"-18 UNF SAE#6 SOCKET-SPL [DD SK 27 A436] | C42: 9/16"-18 UNF SAE#6 SOCKET-SPL | D42: 0.02 | E42: 0.23244444 | G42: EN1A | H42: 1.1 | I42: 7850 | O42: PROX. BLOCK | P42: 5" GLAND
...

Sheet Machining cost
A1: ="MACHINING COST BORE "&'CYLINDER COST'!C17&" X STROKE "&'CYLINDER COST'!C19&" X ROD "&'CYLINDER COST'!C18&" ASSY" -> MACHINING COST BORE 2.5" X STROKE 180MM X ROD 1.5" ASSY
A2: Component | B2: Operation # | C2: Operation description | D2: Machine used | E2: Cycle time (min) | F2: Setup time (min) | G2: Qty per cycle | H2: Machine cost/min (₹) | I2: Machine cost / cycle (₹) | J2: Set up cost (₹) | K2: Set up cost /Qty (₹) | L2: Total cost (₹) | M2: Total cost (USD) | O2: Machine | P2: Cost per minute (₹)
A3: ='CYLINDER COST'!B5 -> TUBE | B3: 1 | C3: Cutting | D3: Circular Saw | E3: 1 | F3: 20 | G3: 10 | H3: =VLOOKUP(D3,$O$3:$P$9,2,false) -> 4.67 | I3: =E3*H3 -> 4.67 | J3: =F3*H3 -> 93.4 | K3: =J3/G3 -> 9.34 | L3: =K3+I3 -> 14.01 | M3: =SUMIF(L3:L6,"<>#DIV/0!")/85 -> 1.2422353 | O3: VMC | P3: 5.83
B4: 2 | C4: Sizing & Facing | D4: Other | E4: 2 | F4: 30 | G4: =G3 -> 10 | H4: =VLOOKUP(D4,$O$3:$P$9,2,false) -> 3 | I4: =E4*H4 -> 6 | J4: =F4*H4 -> 90 | K4: =J4/G4 -> 9 | L4: =K4+I4 -> 15 | O4: CNC | P4: 4.16
B5: 3 | C5: Drilling | D5: Other | E5: 1.5 | F5: 60 | G5: =G4 -> 10 | H5: =VLOOKUP(D5,$O$3:$P$9,2,false) -> 3 | I5: =E5*H5 -> 4.5 | J5: =F5*H5 -> 180 | K5: =J5/G5 -> 18 | L5: =K5+I5 -> 22.5 | O5: Circular Saw | P5: 4.67
B6: 4 | C6: Machining | D6: CNC | E6: 7 | F6: 60 | G6: =G5 -> 10 | H6: =VLOOKUP(D6,$O$3:$P$9,2,false) -> 4.16 | I6: =E6*H6 -> 29.12 | J6: =F6*H6 -> 249.6 | K6: =J6/G6 -> 24.96 | L6: =K6+I6 -> 54.08 | O6: Other | P6: 3
A7: ='CYLINDER COST'!B6 -> PISTON ROD | B7: 1 | C7: Cutting | D7: Circular Saw | E7: 1 | F7: 20 | G7: =G6 -> 10 | H7: =VLOOKUP(D7,$O$3:$P$9,2,false) -> 4.67 | I7: =E7*H7 -> 4.67 | J7: =F7*H7 -> 93.4 | K7: =J7/G7 -> 9.34 | L7: =K7+I7 -> 14.01 | M7: =SUMIF(L7:L9,"<>#DIV/0!")/85 -> 1.1436471
B8: 2 | C8: Turning | D8: CNC | E8: 5 | F8: 45 | G8: =G7 -> 10 | H8: =VLOOKUP(D8,$O$3:$P$9,2,false) -> 4.16 | I8: =E8*H8 -> 20.8 | J8: =F8*H8 -> 187.2 | K8: =J8/G8 -> 18.72 | L8: =K8+I8 -> 39.52
B9: 3 | C9: Turning | D9: CNC | E9: 6 | F9: 45 | G9: =G8 -> 10 | H9: =VLOOKUP(D9,$O$3:$P$9,2,false) -> 4.16 | I9: =E9*H9 -> 24.96 | J9: =F9*H9 -> 187.2 | K9: =J9/G9 -> 18.72 | L9: =K9+I9 -> 43.68
A10: ='CYLINDER COST'!B7 -> PISTON | B10: 1 | C10: Cutting | D10: Circular Saw | E10: 1 | F10: 20 | G10: =G9 -> 10 | H10: =VLOOKUP(D10,$O$3:$P$9,2,false) -> 4.67 | I10: =E10*H10 -> 4.67 | J10: =F10*H10 -> 93.4 | K10: =J10/G10 -> 9.34 | L10: =K10+I10 -> 14.01 | M10: =SUMIF(L10:L12,"<>#DIV/0!")/85 -> 0.70317647
B11: 2 | C11: Turning | D11: CNC | E11: 4 | F11: 20 | G11: =G10 -> 10 | H11: =VLOOKUP(D11,$O$3:$P$9,2,false) -> 4.16 | I11: =E11*H11 -> 16.64 | J11: =F11*H11 -> 83.2 | K11: =J11/G11 -> 8.32 | L11: =K11+I11 -> 24.96
B12: 3 | C12: Turning | D12: CNC | E12: 3 | F12: 20 | G12: =G11 -> 10 | H12: =VLOOKUP(D12,$O$3:$P$9,2,false) -> 4.16 | I12: =E12*H12 -> 12.48 | J12: =F12*H12 -> 83.2 | K12: =J12/G12 -> 8.32 | L12: =K12+I12 -> 20.8
A13: ='CYLINDER COST'!B8 -> GLAND | B13: 1 | C13: Cutting | D13: Circular Saw | E13: 1 | F13: 20 | G13: =G12 -> 10 | H13: =VLOOKUP(D13,$O$3:$P$9,2,false) -> 4.67 | I13: =E13*H13 -> 4.67 | J13: =F13*H13 -> 93.4 | K13: =J13/G13 -> 9.34 | L13: =K13+I13 -> 14.01 | M13: =SUMIF(L13:L15,"<>#DIV/0!")/85 -> 1.1436471
B14: 2 | C14: Turning | D14: CNC | E14: 6 | F14: 30 | G14: =G13 -> 10 | H14: =VLOOKUP(D14,$O$3:$P$9,2,false) -> 4.16 | I14: =E14*H14 -> 24.96 | J14: =F14*H14 -> 124.8 | K14: =J14/G14 -> 12.48 | L14: =K14+I14 -> 37.44
B15: 3 | C15: Turning | D15: CNC | E15: 5 | F15: 60 | G15: =G14 -> 10 | H15: =VLOOKUP(D15,$O$3:$P$9,2,false) -> 4.16 | I15: =E15*H15 -> 20.8 | J15: =F15*H15 -> 249.6 | K15: =J15/G15 -> 24.96 | L15: =K15+I15 -> 45.76
A16: ='CYLINDER COST'!B9 -> END CAP | B16: 1 | C16: Cutting | D16: Circular Saw | E16: 1 | F16: 20 | G16: =G15 -> 10 | H16: =VLOOKUP(D16,$O$3:$P$9,2,false) -> 4.67 | I16: =E16*H16 -> 4.67 | J16: =F16*H16 -> 93.4 | K16: =J16/G16 -> 9.34 | L16: =K16+I16 -> 14.01 | M16: =SUMIF(L16:L18,"<>#DIV/0!")/85 -> 0.60529412
B17: 2 | C17: Turning | D17: CNC | E17: 3 | F17: 20 | G17: =G16 -> 10 | H17: =VLOOKUP(D17,$O$3:$P$9,2,false) -> 4.16 | I17: =E17*H17 -> 12.48 | J17: =F17*H17 -> 83.2 | K17: =J17/G17 -> 8.32 | L17: =K17+I17 -> 20.8
B18: 3 | C18: Turning | D18: CNC | E18: 2 | F18: 20 | G18: =G17 -> 10 | H18: =VLOOKUP(D18,$O$3:$P$9,2,false) -> 4.16 | I18: =E18*H18 -> 8.32 | J18: =F18*H18 -> 83.2 | K18: =J18/G18 -> 8.32 | L18: =K18+I18 -> 16.64
A19: ='CYLINDER COST'!B10 -> ROD CLEVIS | B19: 1 | C19: Cutting | D19: Circular Saw | E19: 1 | F19: 20 | G19: =G18 -> 10 | H19: =VLOOKUP(D19,$O$3:$P$9,2,false) -> 4.67 | I19: =E19*H19 -> 4.67 | J19: =F19*H19 -> 93.4 | K19: =J19/G19 -> 9.34 | L19: =K19+I19 -> 14.01 | M19: =SUMIF(L19:L21,"<>#DIV/0!")/85 -> 0.65423529
B20: 2 | C20: Turning | D20: CNC | E20: 2 | F20: 30 | G20: =G19 -> 10 | H20: =VLOOKUP(D20,$O$3:$P$9,2,false) -> 4.16 | I20: =E20*H20 -> 8.32 | J20: =F20*H20 -> 124.8 | K20: =J20/G20 -> 12.48 | L20: =K20+I20 -> 20.8
B21: 3 | C21: Turning | D21: CNC | E21: 2 | F21: 30 | G21: =G20 -> 10 | H21: =VLOOKUP(D21,$O$3:$P$9,2,false) -> 4.16 | I21: =E21*H21 -> 8.32 | J21: =F21*H21 -> 124.8 | K21: =J21/G21 -> 12.48 | L21: =K21+I21 -> 20.8
A22: ='CYLINDER COST'!B11 -> BACK CLEVIS | B22: 1 | C22: Cutting | D22: Circular Saw | E22: 1 | F22: 20 | G22: =G21 -> 10 | H22: =VLOOKUP(D22,$O$3:$P$9,2,false) -> 4.67 | I22: =E22*H22 -> 4.67 | J22: =F22*H22 -> 93.4 | K22: =J22/G22 -> 9.34 | L22: =K22+I22 -> 14.01 | M22: =SUMIF(L22:L24,"<>#DIV/0!")/85 -> 0.75211765
B23: 2 | C23: Turning | D23: CNC | E23: 3 | F23: 30 | G23: =G22 -> 10 | H23: =VLOOKUP(D23,$O$3:$P$9,2,false) -> 4.16 | I23: =E23*H23 -> 12.48 | J23: =F23*H23 -> 124.8 | K23: =J23/G23 -> 12.48 | L23: =K23+I23 -> 24.96
B24: 3 | C24: Turning | D24: CNC | E24: 3 | F24: 30 | G24: =G23 -> 10 | H24: =VLOOKUP(D24,$O$3:$P$9,2,false) -> 4.16 | I24: =E24*H24 -> 12.48 | J24: =F24*H24 -> 124.8 | K24: =J24/G24 -> 12.48 | L24: =K24+I24 -> 24.96

Sheet Paint cost
A1: CYLINDER SURFACE AREA
A2: Description | B2: Units | C2: Value
A3: Tube Outer Ø | B3: mm | C3: 74
A4: Retracted Length | B4: mm | C4: 480
A5: Cylinder Surface Area | B5: Sq.m | C5: =3.14*C3*C4/10^6 -> 0.1115328
A9: TOTAL PAINT COST PER CYLINDER AREA | D9: PAINT COST
A10: 7 Tank Set Up cost | B10: =C60 -> 1.3437687 | D10: 300
A11: Paint & Thinner Cost | B11: ='Paint cost'!C41 -> 60.46959
A12: Painter & Helper Cost | B12: ='Paint cost'!R46 -> 14.378325
A13: Power Cost | B13: ='Paint cost'!M57 -> 10.24815
A14: Chemical Cost | B14: ='Paint cost'!H54 -> 1.0611293
A15: DM Water Cost | B15: ='Paint cost'!M41 -> 1.003616
A16: Consumable Cost | B16: ='Paint cost'!C52 -> 0.24635759
A17: Total Cost | B17: =SUM(B10:B16)/85 -> 1.0441287
A30: Note :- Only Paint Cost Can able to edit here
A31: INPUTS
A32: Cylinder Area In Sq.m | B32: =C5 -> 0.1115328
A33: Total Sq.m | B33: 2490
A34: PAINT & THINNER CONSUMPTION DETAILS | F34: CHEMICAL CONSUMPTION DETAILS | K34: DM WATER CONSUMPTION DETAILS | P34: LABOUR DETAILS
A35: Description | B35: Units | C35: Value | D35: Formula | F35: Description | G35: Units | H35: Value | I35: Formula | K35: Description | L35: Units | M35: Value | N35: Formula | P35: Description | Q35: Units | R35: Value | S35: Formula
A36: Total Paint & Thinner Consumption | B36: Litre | C36: 4500 | F36: BONDERITE C AK 1352 BA (Total Chemical Consumed) | G36: Kg | H36: 25 | K36: Total DM Water Consumption | L36: Litre | M36: 56015 | P36: Total Painters | Q36: - | R36: 3
A37: Paint & Thinner Consumption Per Sq.m | B37: Litre | C37: =C36/B33 -> 1.8072289 | D37: Paint & Thinner Consumption / Total Sq.m | F37: BONDERITE C AK 1352 BA (Per Sq.m) | G37: Kg | H37: =H36/B33 -> 0.010040161 | I37: Total Kg / Total Sq.m | K37: DM Water Consumption Per Sq.m | L37: Litre | M37: =M36/B33 -> 22.495984 | N37: Total Litres / Total Sq.m | P37: Painters Per Sq.m | Q37: - | R37: =R36/B33 -> 0.0012048193 | S37: Total Painters/ Total Sq.m
A38: PAINT & THINNER CONSUMPTION COST | F38: BONDERITE M NT 1 (Total Chemical Consumed) | G38: Kg | H38: 20 | K38: DM WATER CONSUMPTION COST | P38: Total Helpers | Q38: - | R38: 12
A39: Description | B39: Value | C39: Units | D39: Formula | F39: BONDERITE M NT 1 (Per Sq.m) | G39: Kg | H39: =H38/B33 -> 0.0080321285 | I39: Total Kg / Total Sq.m | K39: Description | L39: Units | M39: Value | N39: Formula | P39: Helpers Per Sq.m | Q39: - | R39: =R38/B33 -> 0.0048192771 | S39: Total Helpers / Total Sq.m
A40: Paint Cost Per Sq.m | B40: Rs | C40: =C37*B43 -> 542.16867 | D40: Litre Per Sq.m * Rate Per Litre | F40: BONDERITE M AD 700 (Total Chemical Consumed) | G40: Kg | H40: 18 | K40: DM Water Consumption Cost Per Sq.m | L40: Rs | M40: =M37*L43 -> 8.9983936 | N40: Water Consumption Per Sq.m * Cost Per Litre | P40: LABOUR COST
A41: Paint & Thinner Consumption Cost For Cylinder Area | B41: Rs | C41: =C40*B32 -> 60.46959 | D41: Paint Cost Per Sq.m * Cylinder Area | F41: BONDERITE M AD 700 (Per Sq.m) | G41: Kg | H41: =H40/B33 -> 0.0072289157 | I41: Total Kg / Total Sq.m | K41: DM Water Consumption Cost For Cylinder Area | L41: Rs | M41: =M40*B32 -> 1.003616 | N41: Water Consumption Per Sq.m * Cylinder Area | P41: Description | Q41: Units | R41: Value | S41: Formula
A42: 1 LITRE COST | F42: BONDERITE C IC 2520 (Total Chemical Consumed) | G42: Kg | H42: 24 | K42: 1 LITRE COST | P42: Total Painters Cost Per Sq.m | Q42: Rs | R42: =R37*Q48 -> 42.168675
A43: Paint | B43: =D10 -> 300 | F43: BONDERITE C IC 2520 (Per Sq.m) | G43: Kg | H43: =H42/B33 -> 0.0096385542 | I43: Total Kg / Total Sq.m | K43: DM WATER | L43: 0.4 | P43: Total Helpers Cost Per Sq.m | Q43: Rs | R43: =R39*Q49 -> 86.746988
F44: CHEMICAL CONSUMPTION COST | P44: Painter Cost for Cylinder Area | Q44: Rs | R44: =R42*B32 -> 4.7031904 | S44: Total Painter Cost Per Sq.m * Cylinder Area
A45: CONSUMABLE CONSUMPTION DETAILS | F45: Description | G45: Units | H45: Value | I45: Formula | K45: POWER CONSUMPTION DETAILS | P45: Helper Cost for Cylinder Area | Q45: Rs | R45: =R43*B32 -> 9.6751345 | S45: Total Painter Cost Per Sq.m * Cylinder Area
A46: Description | B46: Units | C46: Value | D46: Formula | F46: Alkaline Consumption Cost Per Sq.m (BONDERITE C AK 1352 BA) | G46: Rs | H46: =H37*G56 -> 2.5100402 | I46: Chemical Per Sq.m * Rate Per Sq.m | K46: Description | L46: Units | M46: Value | N46: Formula | P46: Total Man Power Cost For Cylinder Area | Q46: Rs | R46: =R44+R45 -> 14.378325
A47: Total Consumables Used | B47: Qty | C47: 11 | F47: Chemical Consumption Cost Per Sq.m (BONDERITE M NT 1 ) | G47: Rs | H47: =H39*G57 -> 3.1726908 | I47: Chemical Per Sq.m * Rate Per Sq.m | K47: Total Power Consumed (Units) - Pre Treatment | L47: Kw | M47: 9953 | P47: Man Power Cost
A48: Consumables Per Sq.m | B48: Qty | C48: =C47/B33 -> 0.0044176707 | D48: Total Consumables Used / Total Sq.m | F48: Chemical Consumption Cost Per Sq.m (BONDERITE M AD 700 ) | G48: Rs | H48: =H41*G58 -> 1.6626506 | I48: Chemical Per Sq.m * Rate Per Sq.m | K48: Power Consumption Per Unit Area (Pre-Treatment) | L48: Kw | M48: =M47/B33 -> 3.9971888 | N48: Total Power Consumed / Total Sq.m | P48: Painters | Q48: 35000
A49: CONSUMABLE CONSUMPTION COST | F49: Chemical Consumption Cost Per Sq.m (BONDERITE C IC 2520 ) | G49: Rs | H49: =H43*G59 -> 2.1686747 | I49: Chemical Per Sq.m * Rate Per Sq.m | K49: Total Power Consumed (Units) - Paint booth | L49: Kw | M49: 18163 | P49: Helpers | Q49: 18000
A50: Description | B50: Units | C50: Value | D50: Formula | F50: Alkaline Consumption Cost For Cylinder Area (BONDERITE C AK 1352 BA) | G50: Rs | H50: =H46*B32 -> 0.27995181 | I50: Alkaline Consumed Per Sq.m * Cylinder Area | K50: Power Consumption Per Unit Area (Paint booth) | L50: Kw | M50: =M49/B33 -> 7.2943775 | N50: Total Power Consumed / Total Sq.m
A51: Consumable Consumption Per Sq.m | B51: Rs | C51: =C48*B54 -> 2.2088353 | D51: Consumable Consumption Per Sq.m * Unit Cost | F51: Chemical Consumption Cost For Cylinder Area (BONDERITE M NT 1 ) | G51: Rs | H51: =H47*B32 -> 0.35385908 | I51: Alkaline Consumed Per Sq.m * Cylinder Area | K51: POWER CONSUMPTION COST
A52: Consumable Consumption For Cylinder Area | B52: Rs | C52: =C51*B32 -> 0.24635759 | D52: Consumable Consumption Per Sq.m * Cylinder Area | F52: Chemical Consumption Cost For Cylinder Area (BONDERITE M AD 700 ) | G52: Rs | H52: =H48*B32 -> 0.18544008 | I52: Alkaline Consumed Per Sq.m * Cylinder Area | K52: Description | L52: Units | M52: Value | N52: Formula
A53: 1 UNIT COST | F53: Chemical Consumption Cost For Cylinder Area (BONDERITE C IC 2520 ) | G53: Rs | H53: =H49*B32 -> 0.24187836 | I53: Alkaline Consumed Per Sq.m * Cylinder Area | K53: Power Consumption Cost Per Sq.m (Pre-Treatment) | L53: Rs | M53: =M48*L59 -> 36.374418 | N53: Power Per Sq.m * Rate Per Sq.m
A54: Consumable | B54: 500 | F54: Total Chemical Consumption Cost For Cylinder area | G54: Rs | H54: =H50+H51+H52+H53 -> 1.0611293 | K54: Power Consumption Cost Per Sq.m (Paint booth) | L54: Rs | M54: =M50*L60 -> 55.510213 | N54: Power Per Sq.m * Rate Per Sq.m
A55: 7 TANK SET UP COST | F55: 1 KG Cost | K55: Power Consumption Cost For Cylinder Area (Pre-Treatment) | L55: Rs | M55: =M53*B32 -> 4.0569407 | N55: Power Consumption Cost Per Sq.m* Cylinder Area
...

Sheet CNC Cost
A1: CNC MACHINING COST
A2: PART | B2: 0.5" | C2: 0.75" | D2: 1.0" | E2: 1.25" | F2: 1.5" | G2: 1.75" | H2: 2.0" | I2: 2.25" | J2: 2.5" | K2: 2.75" | L2: 3.0" | M2: 3.5" | N2: 4.0" | O2: 4.5" | P2: 5.0" | Q2: 5.5" | R2: 6.0" | S2: 7.0" | T2: 8.0" | U2: 10.0" | W2: usd | X2: 88
A3: TUBE | D3: =11.5/X2 -> 0.13068182 | F3: =14.57/X2 -> 0.16556818 | H3: =14.57/X2 -> 0.16556818 | J3: =14.57/X2 -> 0.16556818 | L3: =24/X2 -> 0.27272727 | M3: =24/X2 -> 0.27272727 | N3: =30.9/X2 -> 0.35113636 | O3: =32.43/X2 -> 0.36852273 | P3: =38.95/X2 -> 0.44261364 | Q3: =39.33/X2 -> 0.44693182 | R3: =41.63/X2 -> 0.47306818 | S3: =48.53/X2 -> 0.55147727 | T3: =56.73/X2 -> 0.64465909 | U3: =70.53/X2 -> 0.80147727
A4: PISTON ROD | B4: =15.33/X2 -> 0.17420455 | C4: =16.1/X2 -> 0.18295455 | D4: =17.25/X2 -> 0.19602273 | E4: =18.94/X2 -> 0.21522727 | F4: =22.08/X2 -> 0.25090909 | G4: =25.45/X2 -> 0.28920455 | H4: =31.82/X2 -> 0.36159091 | I4: =40.25/X2 -> 0.45738636 | J4: =46/X2 -> 0.52272727 | K4: =52.52/X2 -> 0.59681818 | L4: =62.87/X2 -> 0.71443182
A5: PSITON | D5: =15.64/X2 -> 0.17772727 | F5: =19.17/X2 -> 0.21784091 | H5: =21.47/X2 -> 0.24397727 | J5: =22.08/X2 -> 0.25090909 | L5: =24/X2 -> 0.27272727 | M5: =26.83/X2 -> 0.30488636 | N5: =30.28/X2 -> 0.34409091 | O5: =32.35/X2 -> 0.36761364 | P5: =36.8/X2 -> 0.41818182 | Q5: =39.87/X2 -> 0.45306818 | R5: =41.02/X2 -> 0.46613636 | S5: =47.53/X2 -> 0.54011364 | T5: =50.98/X2 -> 0.57931818 | U5: =57.5/X2 -> 0.65340909
A6: GLAND
A7: END CAP | D7: =24.38/X2 -> 0.27704545 | F7: =26.22/X2 -> 0.29795455 | H7: =30.36/X2 -> 0.345 | J7: =33.81/X2 -> 0.38420455 | L7: =39.1/X2 -> 0.44431818 | M7: =41.4/X2 -> 0.47045455 | N7: =47.84/X2 -> 0.54363636 | O7: =52.44/X2 -> 0.59590909 | P7: =57.96/X2 -> 0.65863636 | Q7: =63.02/X2 -> 0.71613636 | R7: =69.92/X2 -> 0.79454545 | S7: =78.2/X2 -> 0.88863636 | T7: =87.4/X2 -> 0.99318182
A8: ROD CLEVIS | D8: =18.78/X2 -> 0.21340909 | F8: =19.93/X2 -> 0.22647727 | H8: =21.08/X2 -> 0.23954545 | J8: =25.3/X2 -> 0.2875 | L8: =28.75/X2 -> 0.32670455 | M8: =33.35/X2 -> 0.37897727 | N8: =37.57/X2 -> 0.42693182 | O8: =40.25/X2 -> 0.45738636 | P8: =47.53/X2 -> 0.54011364 | Q8: =52.13/X2 -> 0.59238636 | R8: =57.5/X2 -> 0.65340909 | S8: =61.33/X2 -> 0.69693182 | T8: =65.93/X2 -> 0.74920455 | U8: =73.6/X2 -> 0.83636364
A9: BACK CLEVIS | D9: =24.15/X2 -> 0.27443182 | F9: =25.68/X2 -> 0.29181818 | H9: =28.37/X2 -> 0.32238636 | J9: =32.2/X2 -> 0.36590909 | L9: =36.03/X2 -> 0.40943182 | M9: =39.87/X2 -> 0.45306818 | N9: =43.32/X2 -> 0.49227273 | O9: =49.45/X2 -> 0.56193182 | P9: =55.2/X2 -> 0.62727273 | Q9: =60.95/X2 -> 0.69261364 | R9: =69/X2 -> 0.78409091 | S9: =74.37/X2 -> 0.84511364 | T9: =77.82/X2 -> 0.88431818 | U9: =85.87/X2 -> 0.97579545
